GTCEuStartupEvents.registry('gtceu:machine', event => {

    event.create('aqueous_transformation_processing_center', 'multiblock')
        .rotationState(RotationState.NON_Y_AXIS)
        .machine((holder) => new $StarTThreadingCapableMachine(holder))
        .recipeTypes(['extractor', 'canner', 'fluid_solidifier'])
        .recipeModifiers([GTRecipeModifiers.PARALLEL_HATCH, $StarTRecipeModifiers.BULK_PROCESSING, GTRecipeModifiers.OC_NON_PERFECT_SUBTICK, $StarTRecipeModifiers.THREADING_MACHINE, GTRecipeModifiers.BATCH_MODE])
        .appearanceBlock(() => Block.getBlock('kubejs:subatomically_secure_casing'))
        .pattern(definition => FactoryBlockPattern.start()
            .aisle("                  ", "  BBB             ", " BBBBB            ", " BBBBB            ", " BBBBB            ", "  BBB             ", "                  ", "                  ", "                  ") 
            .aisle(" BBBBB            ", "BBBBBBB           ", "BBBBBBB           ", "BBBBBBB           ", "BBBBBBB           ", "BBBBBBB           ", " BBBBB            ", "                  ", "                  ") 
            .aisle("  BBB             ", " BBCBB            ", "B     B           ", "D  E  B           ", "B     B           ", " BBBBB            ", "  BBB             ", "                  ", "                  ") 
            .aisle("  BBB       BBB   ", " BBCBB      BBB   ", "B     B     BBB   ", "D  E  B           ", "B     B           ", " BBBBB            ", "  BBB             ", "                  ", "                  ") 
            .aisle("  BBB     BBBBBBB ", " BBCBB     FGGGF  ", "B     B   BBBBBBB ", "D  E  B     BDB   ", "B     B     BDB   ", " BBBBB      BDB   ", "  BBB       BDB   ", "            BBB   ", "                  ") 
            .aisle("  BBB    BBBBBBBBB", " BBCBB    BBGGGBB ", "B     BB BBB   BBB", "D  E  BB  BD   DB ", "B     BB  BD   DB ", " BBBBB    BD   DB ", "  BBB     BD   DB ", "           BBBBB  ", "            BBB   ") 
            .aisle("BBBBBBB  BBBBBBBBB", "BBBCBBB  FBGGGGGBF", "B     BBBBB  E  BB", "D  E  BBBBB  E  D ", "B     BBBBB  E  D ", "BBBBBBB   B  E  D ", "BBBBBBB   B  E  D ", "          BBGGGBB ", "           BBBBB  ") 
            .aisle("H BBB H  BBBBBBBBB", " BBCBBBBBBGGGCGGGG", "B        I       B", "D  E     I       B", "B        I       B", " BBBBBBBBB       B", "H BBB H  B       B", "         BBGGGGGBB", "          BBBBBBB ") 
            .aisle("H BBB H  BBBBBBBBB", " BBCBBBBBBGGCCCGGG", "B        I E   E B", "D  EEEEEEI E   E D", "B        I E   E D", " BBBBBBBBB E   E D", "H BBBBBBBB E   E D", "         BBGGGGGBB", "          BBBBBBB ") 
            .aisle("H BBB H  BBBBBBBBB", " BBCBBBBBBGGGCGGGG", "B        I       B", "D  E     I       B", "B        I       B", " BBBBBBBBB       B", "H BBB H  B       B", "         BBGGGGGBB", "          BBBBBBB ") 
            .aisle("BBBBBBB  BBBBBBBBB", "BBBCBBB  FBGGGGGBF", "B     BBBBB  E  BB", "D  E  BBBBB  E  D ", "B     BBBBB  E  D ", "BBBBBBB   B  E  D ", "BBBBBBB   B  E  D ", "          BBGGGBB ", "           BBBBB  ") 
            .aisle("  BBB    BBBBBBBBB", " BBCBB    BBGGGBB ", "B     BB BBB   BBB", "D  E  BB  BD   DB ", "B     BB  BD   DB ", " BBBBB    BD   DB ", "  BBB     BD   DB ", "           BBBBB  ", "            BBB   ") 
            .aisle("  BBB     BBBBBBB ", " BBCBB     FGGGF  ", "B     B   BBBBBBB ", "D  E  B     BDB   ", "B     B     BDB   ", " BBBBB      BDB   ", "  BBB       BDB   ", "            BBB   ", "                  ") 
            .aisle("  BBB       BBB   ", " BBCBB      BBB   ", "B     B     BBB   ", "D  E  B           ", "B     B           ", " BBBBB            ", "  BBB             ", "                  ", "                  ") 
            .aisle("  BBB             ", " BBCBB            ", "B     B           ", "D  E  B           ", "B     B           ", " BBBBB            ", "  BBB             ", "                  ", "                  ") 
            .aisle(" BBBBB            ", "BBBBBBB           ", "BBBJBBB           ", "BBJEJBB           ", "BBBJBBB           ", "BBBBBBB           ", " BBBBB            ", "                  ", "                  ") 
            .aisle("                  ", "  BBB             ", " BBBBB            ", " BB@BB            ", " BBBBB            ", "  BBB             ", "                  ", "                  ", "                  ") 
            .where(" ", Predicates.any())
            .where("B", Predicates.blocks("kubejs:subatomically_secure_casing")
                .or(Predicates.abilities(PartAbility.IMPORT_ITEMS).setPreviewCount(0).setMaxGlobalLimited(20))
                .or(Predicates.abilities(PartAbility.EXPORT_ITEMS).setPreviewCount(0).setMaxGlobalLimited(20))
                .or(Predicates.abilities(PartAbility.IMPORT_FLUIDS).setPreviewCount(0).setMaxGlobalLimited(20))                
                .or(Predicates.abilities(PartAbility.EXPORT_FLUIDS).setPreviewCount(0).setMaxGlobalLimited(20))
                .or(Predicates.abilities(PartAbility.PARALLEL_HATCH).setMaxGlobalLimited(1))
                .or(Predicates.abilities(PartAbility.INPUT_ENERGY).setMaxGlobalLimited(2))
                .or(Predicates.abilities(PartAbility.MAINTENANCE).setExactLimit(1)))
            .where("C", Predicates.blocks("kubejs:rhenotax_coil"))
            .where("D", Predicates.blocks("kubejs:draco_resilient_fusion_glass"))
            .where("E", Predicates.blocks("kubejs:nyanium_pipe_casing"))
            .where("F", Predicates.blocks("start_core:uv_supreme_thread_helix"))
            .where("G", Predicates.blocks("kubejs:nyanium_machine_casing"))
            .where("H", Predicates.blocks("gtceu:abyssal_alloy_frame"))
            .where("I", Predicates.blocks("kubejs:nyanium_heat_escape_casing"))
            .where("J", Predicates.blocks("kubejs:nyanium_firebox_casing"))
            .where("@", Predicates.controller(Predicates.blocks(definition.get())))
            .build())
        .workableCasingModel('kubejs:block/casings/threading/subatomically_secure_casing',
            'gtceu:block/multiblock/implosion_compressor');
            
        });